<mujoco model="wxai">
  <option iterations="50" timestep="0.001" solver="PGS" gravity="0 0 -9.81" />

  <compiler angle="radian" meshdir="meshes" eulerseq="zyx" autolimits="true" />

  <default>
    <joint limited="true" damping="0.01" armature="0.01" frictionloss="0.01" />
    <geom condim="4" contype="1" conaffinity="15" friction="0.9 0.2 0.2" solref="0.001 2" />
    <motor ctrllimited="true" />
    <equality solref="0.001 2" />
    <default class="visualgeom">
      <geom material="visualgeom" condim="1" contype="0" conaffinity="0" />
    </default>
  </default>

  <asset>
    <mesh name="base_link" file="base_link.stl" />
    <mesh name="right/link_1" file="link_1.stl" />
    <mesh name="right/link_2" file="link_2.stl" />
    <mesh name="right/link_3" file="link_3.stl" />
    <mesh name="right/link_4" file="link_4.stl" />
    <mesh name="right/link_5" file="link_5.stl" />
    <mesh name="right/link_6" file="link_6.stl" />
    <mesh name="carriage_right" file="carriage_right.stl" />
    <mesh name="carriage_left" file="carriage_left.stl" />
    <mesh name="camera_mount_d405" file="camera_mount_d405.stl" />
    <mesh name="gripper_left" file="gripper_left.stl" />
    <mesh name="gripper_right" file="gripper_right.stl" />
    <texture name="texplane" type="2d" builtin="checker" rgb1=".0 .0 .0" rgb2=".8 .8 .8" width="100" height="100" />
    <material name="matplane" reflectance="0." texture="texplane" texrepeat="1 1" texuniform="true" />
    <material name="visualgeom" rgba="0.5 0.9 0.2 1" />
  </asset>

  <worldbody>
    <light directional="true" diffuse="0.4 0.4 0.4" specular="0.1 0.1 0.1" pos="0 0 5.0" dir="0 0 -1" castshadow="false" />
    <light directional="true" diffuse="0.6 0.6 0.6" specular="0.2 0.2 0.2" pos="0 0 4" dir="0 0 -1" />
    <geom name="ground" type="plane" pos="0 0 0" size="100 100 0.001" quat="1 0 0 0" material="matplane" condim="3" conaffinity="15" />
    <camera name="fixed" pos="0 -3.0 0.5607096597796515" xyaxes="1 0 0 0 0 1" />
    <camera name="track" mode="trackcom" pos="0 -3.0 0.5607096597796515" xyaxes="1 0 0 0 0 1" />
    <body name="right/root" pos="0 0 0.06070965977965154" quat="1 0 0 0">
      <geom type="mesh" rgba="0.752941 0.752941 0.752941 1" mesh="base_link" class="visual"/>
      <geom type="mesh" rgba="0.752941 0.752941 0.752941 1" mesh="base_link" class="collision"/>
      <body name="right/link_1" pos="0 0 0.05725">
        <inertial pos="-0.00011075 0.00171176 0.0204459" quat="0.313955 0.305238 -0.643575 0.627752" mass="0.152704" diaginertia="0.000203432 0.000173907 8.3521e-05" />
        <joint name="right/joint_0" pos="0 0 0" axis="0 0 1" range="-3.05433 3.05433" actuatorfrcrange="-27 27" />
        <geom type="mesh" rgba="0.752941 0.752941 0.752941 1" mesh="link_1" class="visual"/>
        <geom type="mesh" rgba="0.752941 0.752941 0.752941 1" mesh="link_1" class="collision"/>
        <body name="right/link_2" pos="0.02 0 0.04625">
          <inertial pos="-0.131215 -0.00292583 0.00021345" quat="-0.00123582 0.706546 -0.00109575 0.707665" mass="1.15316" diaginertia="0.0179449 0.0173612 0.00102628" />
          <joint name="right/joint_1" pos="0 0 0" axis="0 1 0" range="0 3.14159" actuatorfrcrange="-27 27" />
          <geom type="mesh" rgba="0.752941 0.752941 0.752941 1" mesh="link_2" class="visual"/>
          <geom type="mesh" rgba="0.752941 0.752941 0.752941 1" mesh="link_2" class="collision"/>
          <body name="right/link_3" pos="-0.264 0 0">
            <inertial pos="0.180836 -0.0009409 0.0555494" quat="0.0103901 0.669684 -0.0033175 0.742566" mass="0.686666" diaginertia="0.00566898 0.00547578 0.00059316" />
            <joint name="right/joint_2" pos="0 0 0" axis="0 -1 0" range="-3.14159 2.35619" actuatorfrcrange="-27 27" />
            <geom type="mesh" rgba="0.752941 0.752941 0.752941 1" mesh="link_3" class="visual"/>
            <geom type="mesh" rgba="0.752941 0.752941 0.752941 1" mesh="link_3" class="collision"/>
            <body name="right/link_4" pos="0.245 0 0.06">
              <inertial pos="0.0579784 0.00027145 0.0588445" quat="0.948688 0.0346237 0.307828 0.0635164" mass="0.457899" diaginertia="0.000670827 0.000661455 0.000288648" />
              <joint name="right/joint_3" pos="0 0 0" axis="0 -1 0" range="-1.5708 1.5708" actuatorfrcrange="-7 7" />
              <geom type="mesh" rgba="0.752941 0.752941 0.752941 1" mesh="link_4" class="visual"/>
              <geom type="mesh" rgba="0.752941 0.752941 0.752941 1" mesh="link_4" class="collision"/>
              <body name="right/link_5" pos="0.06775 0 0.0455">
                <inertial pos="0.00412447 -1.138e-05 -0.0428318" quat="0.496144 0.502128 0.503595 0.498098" mass="0.366939" diaginertia="0.000320622 0.00026751 0.000189108" />
                <joint name="right/joint_4" pos="0 0 0" axis="0 0 -1" range="-1.5708 1.5708" actuatorfrcrange="-7 7" />
                <geom type="mesh" rgba="0.752941 0.752941 0.752941 1" mesh="link_5" class="visual"/>
                <geom type="mesh" rgba="0.752941 0.752941 0.752941 1" mesh="link_5" class="collision"/>
                <body name="right/link_6" pos="0.02895 0 -0.0455">
                  <camera name="cam_left_wrist" pos="0.06231 0.00000 0.05321" euler="-1.57 -1.22 0.0"  resolution="1920 1080" focal="1.93e-3 1.93e-3" sensorsize="0.0037 0.0021" mode="fixed"/>
                  <inertial pos="0.0449291 0.00141352 0.00918062" quat="0.602152 0.690208 -0.29686 0.27" mass="0.672874" diaginertia="0.00127648 0.0012351 0.000903617" />
                  <joint name="right/joint_5" pos="0 0 0" axis="1 0 0" range="-3.14159 3.14159" actuatorfrcrange="-7 7" />
                  <geom type="mesh" rgba="0.752941 0.752941 0.752941 1" mesh="link_6" class="visual"/>
                  <geom type="mesh" rgba="0.752941 0.752941 0.752941 1" mesh="link_6" class="collision"/>
                  <geom type="mesh" rgba="0.752941 0.752941 0.752941 1" mesh="camera_mount_d405" class="visual"/>
                  <geom type="mesh" rgba="0.752941 0.752941 0.752941 1" mesh="camera_mount_d405" class="collision"/>
                  <geom size="0.0115 0.021 0.021" pos="0.0393206 0 0.0569399" quat="0.984808 0 0.173648 0" type="box" class="visual"/>
                  <geom type="box" rgba="" size="0.0115 0.021 0.021" pos="0.0393206 0 0.0569399" quat="0.984808 0 0.173648 0" />
                  <body name="right/carriage_right" pos="0.0745 -0.023 0">
                    <inertial pos="0.00169015 0.00592793 0.00201817" quat="-0.370973 0.740886 -0.0847721 0.553427" mass="0.081271" diaginertia="4.29565e-05 3.87081e-05 2.21528e-05" />
                    <joint name="right/right/right_carriage_joint" pos="0 0 0" axis="0 -1 0" type="slide" range="0 0.022" actuatorfrcrange="-400 400" />
                    <geom type="mesh" rgba="0.752941 0.752941 0.752941 1" mesh="carriage_right" class="visual"/>
                    <geom type="mesh" rgba="0.752941 0.752941 0.752941 1" mesh="carriage_right" />
                    <geom type="mesh" rgba="0.752941 0.752941 0.752941 1" mesh="gripper_right" class="visual"/>
                    <geom type="mesh" rgba="0.752941 0.752941 0.752941 1" mesh="gripper_right" class="collision"/>
                  </body>
                  <body name="carriage_left" pos="0.0745 0.023 0">
                    <inertial pos="0.00169017 -0.00592796 -0.00365701" quat="-0.0382691 0.628022 -0.255101 0.734198" mass="0.081271" diaginertia="4.21112e-05 3.61943e-05 2.40003e-05" />
                    <joint name="right/left_carriage_joint" pos="0 0 0" axis="0 1 0" type="slide" range="0 0.022" actuatorfrcrange="-400 400" />
                    <geom type="mesh" rgba="0.752941 0.752941 0.752941 1" mesh="carriage_left" class="visual"/>
                    <geom type="mesh" rgba="0.752941 0.752941 0.752941 1" mesh="carriage_left" class="collision"/>
                    <geom type="mesh" rgba="0.752941 0.752941 0.752941 1" mesh="gripper_left" class="visual"/>
                    <geom type="mesh" rgba="0.752941 0.752941 0.752941 1" mesh="gripper_left" class="collision"/>
                  </body>
                </body>
              </body>
            </body>
          </body>
        </body>
      </body>
    </body>
  </worldbody>

  <actuator>
    <motor name="joint_0" joint="joint_0" ctrllimited="true" ctrlrange="-27 27" gear="1" />
    <motor name="joint_1" joint="joint_1" ctrllimited="true" ctrlrange="-27 27" gear="1" />
    <motor name="joint_2" joint="joint_2" ctrllimited="true" ctrlrange="-27 27" gear="1" />
    <motor name="joint_3" joint="joint_3" ctrllimited="true" ctrlrange="-7 7" gear="1" />
    <motor name="joint_4" joint="joint_4" ctrllimited="true" ctrlrange="-7 7" gear="1" />
    <motor name="joint_5" joint="joint_5" ctrllimited="true" ctrlrange="-7 7" gear="1" />
    <motor name="right_carriage_joint" joint="right_carriage_joint" ctrllimited="true" ctrlrange="-400 400" gear="1" />
    <motor name="left_carriage_joint" joint="left_carriage_joint" ctrllimited="true" ctrlrange="-400 400" gear="1" />
  </actuator>

  <sensor>
    <actuatorpos name="joint_0_p" actuator="joint_0" />
    <actuatorvel name="joint_0_v" actuator="joint_0" />
    <actuatorfrc name="joint_0_f" actuator="joint_0" noise="0.001" />
    <actuatorpos name="joint_1_p" actuator="joint_1" />
    <actuatorvel name="joint_1_v" actuator="joint_1" />
    <actuatorfrc name="joint_1_f" actuator="joint_1" noise="0.001" />
    <actuatorpos name="joint_2_p" actuator="joint_2" />
    <actuatorvel name="joint_2_v" actuator="joint_2" />
    <actuatorfrc name="joint_2_f" actuator="joint_2" noise="0.001" />
    <actuatorpos name="joint_3_p" actuator="joint_3" />
    <actuatorvel name="joint_3_v" actuator="joint_3" />
    <actuatorfrc name="joint_3_f" actuator="joint_3" noise="0.001" />
    <actuatorpos name="joint_4_p" actuator="joint_4" />
    <actuatorvel name="joint_4_v" actuator="joint_4" />
    <actuatorfrc name="joint_4_f" actuator="joint_4" noise="0.001" />
    <actuatorpos name="joint_5_p" actuator="joint_5" />
    <actuatorvel name="joint_5_v" actuator="joint_5" />
    <actuatorfrc name="joint_5_f" actuator="joint_5" noise="0.001" />
    <actuatorpos name="right_carriage_joint_p" actuator="right_carriage_joint" />
    <actuatorvel name="right_carriage_joint_v" actuator="right_carriage_joint" />
    <actuatorfrc name="right_carriage_joint_f" actuator="right_carriage_joint" noise="0.001" />
    <actuatorpos name="left_carriage_joint_p" actuator="left_carriage_joint" />
    <actuatorvel name="left_carriage_joint_v" actuator="left_carriage_joint" />
    <actuatorfrc name="left_carriage_joint_f" actuator="left_carriage_joint" noise="0.001" />
    <framequat name="orientation" objtype="site" noise="0.001" objname="imu" />
    <gyro name="angular-velocity" site="imu" noise="0.005" cutoff="34.9" />
  </sensor>
</mujoco>
